Workbook

Sheet Lista maestra
A1: Prioridad modelar | B1: Producto/Página | C1: Origen | D1: Nicho | E1: Tipo de producto | F1: Score | G1: Confianza | H1: Veredicto | I1: Antigüedad (días, cota inferior) | J1: Anuncios activos hoy | K1: Anuncios activos antes | L1: Países/idiomas | M1: Competidores (misma oferta) | N1: Saturación | O1: Riesgo compliance | P1: Avatar | Q1: Necesidad | R1: País con mejor potencial | S1: Tendencia | T1: Link de referencia | U1: Notas de medición | V1: Fecha chequeo
A2: 1 | B2: Aprende y Emprende (moldes de cuero y bolsos, voseo) | C2: Mi búsqueda 04/10 | D2: Marroquinería / bolsos | E2: Pack de moldes | F2: ='Score detalle'!H2 | G2: Media | H2: =IF(F2>=80,"🟢🟢 GANADOR FUERTE",IF(F2>=60,"🟢 GANADOR",IF(F2>=40,"🟡 POTENCIAL","🔴 DESCARTAR"))) | I2: 33 | J2: 33 | K2: 7 | L2: Argentina (copy con precio en ARS $5.000); moneda USD | M2: 1-2 (Aprende ya, PE, +1000 moldes de bolsas) | N2: No | O2: No detectado | P2: Mujeres 28-55 que hacen bolsos o quieren emprender | Q2: Ingreso extra | R2: Argentina primero; luego Perú/Colombia con variante neutra | S2: ↑ (7→33 anuncios) | T2: https://www.facebook.com/ads/library/?id=2133118737279882 | U2: 2 oleadas: coser (09/2026) y moldes de cuero (actual). Casi sin competencia directa. | V2: 2026-10-04
A3: 4 | B3: Udemia.IA (mini-cursos 'Dominá X en 7 días') | C3: Tu planilla 30/09 | D3: IA / productividad | E3: Mini-cursos IA | F3: ='Score detalle'!H3 | G3: Media | H3: =IF(F3>=80,"🟢🟢 GANADOR FUERTE",IF(F3>=60,"🟢 GANADOR",IF(F3>=40,"🟡 POTENCIAL","🔴 DESCARTAR"))) | I3: 8 | J3: 411 | K3: 336 | L3: Argentina (88-178 anuncios), LATAM, ES/EE.UU. | M3: ~6 con oferta parecida; 25+ páginas con cursos IA (en AR solo Udemia) | N3: No | O3: No detectado | P3: Adultos 30-60 que sienten que se quedan atrás con la IA | Q3: Aprender una habilidad | R3: Argentina y México (voseo) | S3: ↑ (336→411) | T3: https://www.facebook.com/ads/library/?id=1108972755201032 | U3: Edad verificable solo ≥8 d (el sistema muestra 50 más recientes); ya tenía 4,7+ d el 30/09. | V3: 2026-10-04
A4: 3 | B4: Navidad Creativa | C4: Mi búsqueda 04/10 | D4: Manualidades navideñas | E4: Curso online | F4: ='Score detalle'!H4 | G4: Media | H4: =IF(F4>=80,"🟢🟢 GANADOR FUERTE",IF(F4>=60,"🟢 GANADOR",IF(F4>=40,"🟡 POTENCIAL","🔴 DESCARTAR"))) | I4: 29 | J4: 73 | K4: 73 | L4: Colombia (COP) | M4: ~5 similares sin verificar idénticos | N4: No | O4: No detectado | P4: Mujeres 30-55 que venden artesanías de temporada | Q4: Ingreso extra de fin de año | R4: Colombia; Argentina/Perú/México con adaptación (temporada ya abierta) | S4: → (73→73) | T4: https://www.facebook.com/ads/library/?id=929011006522905 | U4: ESTACIONAL: la ventana es oct-dic. Hay que lanzar ya. | V4: 2026-10-04
A5: 5 | B5: Emprende con Arte (crochet 70% OFF) | C5: Mi búsqueda 04/10 | D5: Crochet | E5: Curso online | F5: ='Score detalle'!H5 | G5: Media | H5: =IF(F5>=80,"🟢🟢 GANADOR FUERTE",IF(F5>=60,"🟢 GANADOR",IF(F5>=40,"🟡 POTENCIAL","🔴 DESCARTAR"))) | I5: 38.7 | J5: 62 | K5: 6 | L5: USD (países no medidos) | M5: 1-2 (Academia Manualidades Rentables) | N5: No | O5: Urgencia agresiva (riesgo medio) | P5: Mujeres 30-60 que quieren aprender crochet | Q5: Aprender habilidad | R5: Colombia o Perú (estimado) | S5: ↑ (6→62; la 1ª medición subestimó) | T5: https://www.facebook.com/ads/library/?id=1779727460028144 | U5: Corrección: el 1er chequeo había contado solo 6 anuncios. | V5: 2026-10-04
A6: 6 | B6: Conocimiento Digital (megapack moldes de costura) | C6: Tu planilla 30/09 | D6: Costura / moldes | E6: Megapack PDF | F6: ='Score detalle'!H6 | G6: Media | H6: =IF(F6>=80,"🟢🟢 GANADOR FUERTE",IF(F6>=60,"🟢 GANADOR",IF(F6>=40,"🟡 POTENCIAL","🔴 DESCARTAR"))) | I6: 32 | J6: 140 | K6: 135 | L6: Centroamérica y andinos (85 anuncios el 30/09); moneda USD | M6: 25+ en la categoría (1 con texto casi idéntico) | N6: Sí | O6: No visible | P6: Mujeres 35-60 que cosen en casa | Q6: Ingresos extra / oficio | R6: Ecuador, Guatemala, Bolivia (CPM bajo) | S6: → (135→140) | T6: https://www.facebook.com/ads/library/?id=1400702291409435 | U6: Todos los anuncios con el mismo título. Edad real puede ser mayor. | V6: 2026-10-04
A7: 7 | B7: Carpintería para todos | C7: Mi búsqueda 04/10 | D7: Carpintería / planos | E7: Planos y curso | F7: ='Score detalle'!H7 | G7: Media | H7: =IF(F7>=80,"🟢🟢 GANADOR FUERTE",IF(F7>=60,"🟢 GANADOR",IF(F7>=40,"🟡 POTENCIAL","🔴 DESCARTAR"))) | I7: 11.5 | J7: 145 | K7: 50 | L7: Colombia (COP) | M7: 6+ (Productos Virales Pro, Melamina Desing 2026, Emprende Digital...) | N7: No | O7: No detectado | P7: Hombres 25-55 que buscan oficio o ingreso extra | Q7: Aprender oficio / ingreso extra | R7: Colombia; Perú/Bolivia | S7: ↑ (50→145) | T7: https://www.facebook.com/ads/library/?id=1075331462024005 | U7: Crecimiento fuerte; edad por cota inferior. | V7: 2026-10-04
A8: 8 | B8: La Biblioteca Definitiva De Tejido | C8: Mi búsqueda 04/10 | D8: Tejido / crochet | E8: Biblioteca de patrones PDF | F8: ='Score detalle'!H8 | G8: Media | H8: =IF(F8>=80,"🟢🟢 GANADOR FUERTE",IF(F8>=60,"🟢 GANADOR",IF(F8>=40,"🟡 POTENCIAL","🔴 DESCARTAR"))) | I8: 21.2 | J8: 54 | K8: 54 | L8: USD, copy en español (países no medidos) | M8: 2 (Rincón de Crochet, El Club del Tejido) | N8: No | O8: No detectado | P8: Mujeres 35-65 aficionadas al tejido | Q8: Ingreso extra / habilidad | R8: Colombia o Perú (estimado) | S8: → (54→54) | T8: https://www.facebook.com/ads/library/?id=1753228152684059 | U8: Un solo creativo repetido. | V8: 2026-10-04
A9: 9 | B9: Mundo Creativo (+2000 moldes goma eva) | C9: Mi búsqueda 04/10 | D9: Manualidades | E9: Pack de moldes | F9: ='Score detalle'!H9 | G9: Media | H9: =IF(F9>=80,"🟢🟢 GANADOR FUERTE",IF(F9>=60,"🟢 GANADOR",IF(F9>=40,"🟡 POTENCIAL","🔴 DESCARTAR"))) | I9: 17.3 | J9: 29 | K9: 29 | L9: USD | M9: 2 (Mundo Foami PE, ARTE Digital) | N9: No | O9: No detectado | P9: Mamás y maestras que hacen manualidades | Q9: Ingreso extra / ahorro | R9: Perú/Colombia (estimado) | S9: → (29→29) | T9: https://www.facebook.com/ads/library/?id=1435345688695403 | V9: 2026-10-04
A10: 10 | B10: 1500 Moldes de Costura | C10: Ambas (tu planilla y mi lista) | D10: Costura / moldes | E10: Megapack PDF | F10: ='Score detalle'!H10 | G10: Media | H10: =IF(F10>=80,"🟢🟢 GANADOR FUERTE",IF(F10>=60,"🟢 GANADOR",IF(F10>=40,"🟡 POTENCIAL","🔴 DESCARTAR"))) | I10: 10 | J10: 68 | K10: 42 | L10: LATAM (36 en AR/MX/CO/CL/PE el 30/09; 168 estimados en AR hoy) | M10: 25+ páginas con packs de moldes | N10: Sí | O10: No visible | P10: Mujeres 30-55 principiantes en costura | Q10: Ingreso extra / ahorro | R10: México, Colombia, Argentina | S10: ↑ (42→68 vs 30/09) | T10: https://www.facebook.com/ads/library/?id=1021274244315222 | U10: Edad: la muestra actual solo muestra ≥4,9 d; se mantiene 10 d de la medición previa. | V10: 2026-10-04
A11: 11 | B11: MonteAgro (manuales técnicos de cultivo) | C11: Tu planilla 30/09 | D11: Agro / manuales | E11: Manuales PDF + bonos | F11: ='Score detalle'!H11 | G11: Media | H11: =IF(F11>=80,"🟢🟢 GANADOR FUERTE",IF(F11>=60,"🟢 GANADOR",IF(F11>=40,"🟡 POTENCIAL","🔴 DESCARTAR"))) | I11: 6.3 | J11: 108 | K11: 72 | L11: Colombia (12), México (11), PE/EC/GT/AR | M11: 0 con la misma oferta | N11: No | O11: No detectado | P11: Productores 30-60 (mayoría hombres) | Q11: Resolver un problema concreto | R11: Colombia, Perú, México, Ecuador | S11: ↑ (72→108) | T11: https://www.facebook.com/ads/library/?id=2204042687044153 | U11: Casi sin competidores, pero edad todavía corta: aún no validado en el tiempo. | V11: 2026-10-04
A12: — | B12: Biblioteca Digital (planos y oficios) | C12: Mi búsqueda 04/10 | D12: Oficios / planos | E12: Biblioteca de planos | F12: ='Score detalle'!H12 | G12: Media | H12: =IF(F12>=80,"🟢🟢 GANADOR FUERTE",IF(F12>=60,"🟢 GANADOR",IF(F12>=40,"🟡 POTENCIAL","🔴 DESCARTAR"))) | I12: 3.1 | J12: 26 | K12: 26 | L12: USD | M12: 4+ (Los Planos De Dios, Emprende Digital...) | N12: No | O12: No detectado | P12: Hombres 25-55 de oficios | Q12: Aprender oficio | R12: México o Perú (estimado) | S12: → (26→26) | T12: https://www.facebook.com/ads/library/?id=29064207783177270 | U12: Todo reciente. | V12: 2026-10-04
A13: — | B13: Amigurumi Navideño | C13: Tu planilla 30/09 | D13: Crochet / amigurumi | E13: Patrones PDF | F13: ='Score detalle'!H13 | G13: Media | H13: =IF(F13>=80,"🟢🟢 GANADOR FUERTE",IF(F13>=60,"🟢 GANADOR",IF(F13>=40,"🟡 POTENCIAL","🔴 DESCARTAR"))) | I13: 20.3 | J13: 15 | K13: 14 | L13: España (13) + LATAM (14) el 30/09; moneda BRL | M13: 3 + 2 probables | N13: No | O13: Medio: '+2.632 reseñas' sin fuente | P13: Mujeres 35-65 que tejen | Q13: Hobby / regalos navideños | R13: España oct-dic | S13: → (14→15) | T13: https://www.facebook.com/ads/library/?id=1099691303006877 | U13: Estacional. | V13: 2026-10-04
A14: — | B14: Sofia Fernández (moldes de costura) | C14: Tu planilla 30/09 | D14: Costura / moldes | E14: Megapack PDF | F14: ='Score detalle'!H14 | G14: Media | H14: =IF(F14>=80,"🟢🟢 GANADOR FUERTE",IF(F14>=60,"🟢 GANADOR",IF(F14>=40,"🟡 POTENCIAL","🔴 DESCARTAR"))) | I14: 16 | J14: 47 | K14: 25 | L14: España (a confirmar); moneda USD | M14: 25+ en la categoría | N14: Sí | O14: No visible | P14: Mujeres 35-65, costura como hobby | Q14: Hobby creativo | R14: España | S14: ↑ (25→47) | T14: https://www.facebook.com/ads/library/?id=1084333387519565 | V14: 2026-10-04
A15: — | B15: Melissa Amicraft (amigurumi, pets por raza) | C15: Tu planilla 30/09 | D15: Crochet / amigurumi | E15: Patrones PDF | F15: ='Score detalle'!H15 | G15: Media | H15: =IF(F15>=80,"🟢🟢 GANADOR FUERTE",IF(F15>=60,"🟢 GANADOR",IF(F15>=40,"🟡 POTENCIAL","🔴 DESCARTAR"))) | I15: 6.4 | J15: 36 | K15: 26 | L15: España + Brasil (PT/ES); moneda BRL | M15: 15+ en crochet | N15: Sí | O15: No | P15: Mujeres 30-60 que tejen; dueños de mascotas | Q15: Hobby / regalo | R15: España (cruza con mascotas) | S15: ↑ (26→36) | T15: https://www.facebook.com/ads/library/?id=1124573633340085 | V15: 2026-10-04
A16: — | B16: Fermentados y kombucha (Escuela Vegetariana) | C16: Mi búsqueda 04/10 | D16: Fermentados | E16: Curso online | F16: ='Score detalle'!H16 | G16: Media | H16: =IF(F16>=80,"🟢🟢 GANADOR FUERTE",IF(F16>=60,"🟢 GANADOR",IF(F16>=40,"🟡 POTENCIAL","🔴 DESCARTAR"))) | I16: 129.5 | J16: 31 | K16: 5 | L16: EUR (España) | M16: 1 (Dr. Grappin MX) | N16: No | O16: Riesgo medio: claims de probióticos | P16: Adultos 30-55 interesados en alimentación saludable | Q16: Aprender habilidad | R16: México/España | S16: → | T16: https://www.facebook.com/ads/library/?id=959183153555702 | U16: 31 anuncios, pero casi todos de catálogo dinámico; solo 3 propios de fermentación. | V16: 2026-10-04
A17: — | B17: MundoManuarte (velas artesanales) | C17: Tu planilla 30/09 | D17: Velas artesanales | E17: Curso/pack + WhatsApp | F17: ='Score detalle'!H17 | G17: Media | H17: =IF(F17>=80,"🟢🟢 GANADOR FUERTE",IF(F17>=60,"🟢 GANADOR",IF(F17>=40,"🟡 POTENCIAL","🔴 DESCARTAR"))) | I17: 76.9 | J17: 8 | K17: 9 | L17: No medido; moneda USD | M17: 5 (por título) | N17: No | O17: No | P17: Mujeres 25-50 que quieren emprender desde casa | Q17: Ingresos extra | R17: No medido | S17: → (9→8) | T17: https://www.facebook.com/ads/library/?id=1485691479934180 | U17: Longevo pero pocos anuncios. | V17: 2026-10-04
A18: — | B18: Mentoría Global (empaques premium) | C18: Mi búsqueda 04/10 | D18: Emprendimiento / empaques | E18: Plantillas y mentoría | F18: ='Score detalle'!H18 | G18: Media | H18: =IF(F18>=80,"🟢🟢 GANADOR FUERTE",IF(F18>=60,"🟢 GANADOR",IF(F18>=40,"🟡 POTENCIAL","🔴 DESCARTAR"))) | I18: 3.1 | J18: 60 | K18: 60 | L18: USD | M18: 0 idénticos | N18: No | O18: No detectado | P18: Emprendedoras de productos artesanales | Q18: Ingreso extra | R18: No medido | S18: → (60→60) | T18: https://www.facebook.com/ads/library/?id=2053473725373198 | V18: 2026-10-04
A19: — | B19: Aprenda a Fazer Queijo (quesos) | C19: Mi búsqueda 04/10 | D19: Quesos artesanales | E19: Curso online | F19: ='Score detalle'!H19 | G19: Baja | H19: =IF(F19>=80,"🟢🟢 GANADOR FUERTE",IF(F19>=60,"🟢 GANADOR",IF(F19>=40,"🟡 POTENCIAL","🔴 DESCARTAR"))) | I19: 356 | J19: 8 | K19: 8 | L19: BRL; copy en español | M19: 3 (1er chequeo) | N19: No | O19: No detectado | P19: Adultos 30-60 | Q19: Ingreso extra / habilidad | R19: México o Perú (estimado) | S19: Sin dato hoy (página no encontrada) | T19: https://www.facebook.com/ads/library/?id=777761838222224 | U19: No se pudo re-medir hoy; datos del 1er chequeo. | V19: 2026-10-04
A20: — | B20: Cursos de adiestramiento canino (EducaT Digital) | C20: Mi búsqueda 04/10 | D20: Mascotas / adiestramiento | E20: Curso online low ticket | F20: ='Score detalle'!H20 | G20: Media | H20: =IF(F20>=80,"🟢🟢 GANADOR FUERTE",IF(F20>=60,"🟢 GANADOR",IF(F20>=40,"🟡 POTENCIAL","🔴 DESCARTAR"))) | I20: 9.3 | J20: 3 | K20: 3 | L20: MXN | M20: ~3 (Jack Store PE, Mundo Mascotas...) | N20: No | O20: No detectado | P20: Dueños de perros 25-50 | Q20: Resolver un problema | R20: México | S20: ↓ (ref. de 156 d ya no figura) | T20: https://www.facebook.com/ads/library/?id=1393020595713303 | U20: Página con 11 anuncios, solo 3 del curso canino. | V20: 2026-10-04
A21: — | B21: Juana Castro (moldes de costura) | C21: Tu planilla 30/09 | D21: Costura / moldes | E21: Megapack PDF | F21: ='Score detalle'!H21 | G21: Baja | H21: =IF(F21>=80,"🟢🟢 GANADOR FUERTE",IF(F21>=60,"🟢 GANADOR",IF(F21>=40,"🟡 POTENCIAL","🔴 DESCARTAR"))) | I21: 3.4 | J21: 66 | K21: 66 | L21: España + inglés (30/09) | M21: 25+ en la categoría | N21: Sí | O21: Medio: '+480 reseñas' sin fuente | P21: Mujeres 35-65 | Q21: Aprender / hobby | R21: España | S21: ↓ (66→0 hoy: no aparece) | T21: https://www.facebook.com/ads/library/?id=1103745219075117 | U21: Hoy 0 resultados; datos del 30/09. | V21: 2026-10-04
A22: — | B22: NUVIA Recetario Digital | C22: Mi búsqueda 04/10 | D22: Recetas / packaging | E22: Ebook bundle | F22: ='Score detalle'!H22 | G22: Media | H22: =IF(F22>=80,"🟢🟢 GANADOR FUERTE",IF(F22>=60,"🟢 GANADOR",IF(F22>=40,"🟡 POTENCIAL","🔴 DESCARTAR"))) | I22: 5.6 | J22: 15 | K22: 3 | L22: USD y ARS | M22: 0 idénticos | N22: No | O22: No detectado | P22: Emprendedoras de repostería | Q22: Ingreso extra | R22: Argentina | S22: ↑ (3→15) | T22: https://www.facebook.com/ads/library/?id=4535732786648361 | U22: Cambió de ángulo a moldes + packaging imprimibles. | V22: 2026-10-04
A23: — | B23: Habilidades Esenciales (pack 7 libros) | C23: Tu planilla 30/09 | D23: Autosuficiencia | E23: Pack de libros | F23: ='Score detalle'!H23 | G23: Baja | H23: =IF(F23>=80,"🟢🟢 GANADOR FUERTE",IF(F23>=60,"🟢 GANADOR",IF(F23>=40,"🟡 POTENCIAL","🔴 DESCARTAR"))) | I23: 3.6 | J23: 32 | K23: 32 | L23: Global (AR, ES, EE.UU., MX el 30/09) | M23: 1 (+1 clon) | N23: No | O23: Medio: ganchos de miedo | P23: Hombres y mujeres 40-65 rurales/nostálgicos | Q23: Resolver un problema | R23: Colombia, México, Argentina | S23: Sin dato hoy (3 intentos sin hallar la página) | T23: https://www.facebook.com/ads/library/?id=2950078028696907 | U23: No re-medido. | V23: 2026-10-04
A24: — | B24: She Fixed (reparaciones del hogar, inglés) | C24: Tu planilla 30/09 | D24: Hogar / reparaciones | E24: Manual (EN) | F24: ='Score detalle'!H24 | G24: Baja | H24: =IF(F24>=80,"🟢🟢 GANADOR FUERTE",IF(F24>=60,"🟢 GANADOR",IF(F24>=40,"🟡 POTENCIAL","🔴 DESCARTAR"))) | I24: 49.5 | J24: 20 | K24: 20 | L24: EE.UU. + GB/CA/AU/IE | M24: 1 (sin versión en español) | N24: No | O24: No | P24: Mujeres 30-65 independientes | Q24: Resolver un problema | R24: España/Argentina/México (nadie lo vende en español) | S24: Sin dato hoy (5 intentos, también en estado ALL) | T24: https://www.facebook.com/ads/library/?id=1644153120559023 | U24: En Polonia aparece un entrante similar: 'Ona to Naprawiła' (1 anuncio, <1 d). | V24: 2026-10-04
A25: — | B25: Método Aprende y Emprende (repostería) | C25: Tu planilla 30/09 | D25: Repostería para vender | E25: Recetario/curso | F25: ='Score detalle'!H25 | G25: Baja | H25: =IF(F25>=80,"🟢🟢 GANADOR FUERTE",IF(F25>=60,"🟢 GANADOR",IF(F25>=40,"🟡 POTENCIAL","🔴 DESCARTAR"))) | I25: 55 | J25: 6 | K25: 6 | L25: No medido | M25: 20+ (categoría) | N25: Sí | O25: No | P25: Mujeres 25-50 | Q25: Ingresos extra | R25: No medido | S25: Sin dato hoy (página no hallada) | T25: https://www.facebook.com/ads/library/?id=1520776935928755 | U25: No re-medido. | V25: 2026-10-04
A26: — | B26: EmprendeEbook (+70 recetas sin horno) | C26: Mi búsqueda 04/10 | D26: Recetas / repostería | E26: Ebook de recetas | F26: ='Score detalle'!H26 | G26: Media | H26: =IF(F26>=80,"🟢🟢 GANADOR FUERTE",IF(F26>=60,"🟢 GANADOR",IF(F26>=40,"🟡 POTENCIAL","🔴 DESCARTAR"))) | I26: 1.1 | J26: 7 | K26: 7 | L26: USD | M26: 0 encontrados | N26: No | O26: No detectado | P26: Mujeres 25-55 en verano austral | Q26: Ahorro / ingreso extra | R26: Argentina (verano) | S26: → (7→7) | T26: https://www.facebook.com/ads/library/?id=1121432810405652 | V26: 2026-10-04
A27: — | B27: NuBook / Cempra (paneles solares) | C27: Mi búsqueda 04/10 | D27: Energía solar | E27: Curso/ebook low ticket | F27: ='Score detalle'!H27 | G27: Media | H27: =IF(F27>=80,"🟢🟢 GANADOR FUERTE",IF(F27>=60,"🟢 GANADOR",IF(F27>=40,"🟡 POTENCIAL","🔴 DESCARTAR"))) | I27: 12.9 | J27: 6 | K27: 3 | L27: USD | M27: Competidores son cursos presenciales | N27: No | O27: No detectado | P27: Hombres 25-50 de oficios | Q27: Aprender oficio | R27: Perú o México (estimado) | S27: ↑ (3→6) | T27: https://www.facebook.com/ads/library/?id=1728388291573918 | V27: 2026-10-04
A28: — | B28: The Knowhow Co. (multi mini-productos EE.UU.) | C28: Tu planilla 30/09 | D28: Multitienda EE.UU. | E28: Mini-productos $37 | F28: ='Score detalle'!H28 | G28: Baja | H28: =IF(F28>=80,"🟢🟢 GANADOR FUERTE",IF(F28>=60,"🟢 GANADOR",IF(F28>=40,"🟡 POTENCIAL","🔴 DESCARTAR"))) | I28: 4.1 | J28: 2 | K28: 89 | L28: EE.UU. | M28: N/A | N28: No | O28: Medio: tema legal sensible | P28: Varios | Q28: Varía | R28: EE.UU. | S28: ↓ (89→2; posible otra página) | T28: https://www.facebook.com/ads/library/?id=2180057416221838 | U28: Referencia de modelo de negocio, no de producto. | V28: 2026-10-04
A29: — | B29: Geriactiva (biblioteca +1000 recursos para tercera edad) | C29: Pedido tuyo 04/10 | D29: Adultos mayores / estimulación cognitiva | E29: Biblioteca de recursos/actividades PDF | F29: ='Score detalle'!H29 | G29: Media | H29: =IF(F29>=80,"🟢🟢 GANADOR FUERTE",IF(F29>=60,"🟢 GANADOR",IF(F29>=40,"🟡 POTENCIAL","🔴 DESCARTAR"))) | I29: 3.2 | J29: 182 | K29: — | L29: Moneda USD; países no medidos | M29: 6+ (Academia Digital +1000 actividades, Mente Activa 7 cuadernillos, Mente activa AR, Campo Psi Recursos AR, Mente Despierta BR, ActivaSenior ES) | N29: No | O29: No detectado | P29: Terapeutas ocupacionales, animadores de geriátricos y cuidadores (por los títulos: 'armar la sesión desde cero'); familiares | Q29: Resolver un problema / ahorrar tiempo | R29: Argentina (hay competidores locales en ARS y muchas residencias geriátricas) y México | S29: Primer chequeo | T29: https://www.facebook.com/ads/library/?id=2363989227680463 | U29: Los anuncios más viejos vistos son de hace ~3 días (muestra de 50 de 182); 3 ángulos: '+3000 profesionales lo recomiendan', 'biblioteca +1000', 'deja de armar la sesión'. Hay que re-chequear en 7 días. | V29: 2026-10-04
A30: — | B30: Šicí cirkus (patrones y cursos de costura, Chequia) | C30: Mi búsqueda Europa del Este 04/10 | D30: Costura / patrones | E30: Patrones PDF + cursos | F30: ='Score detalle'!H30 | G30: Baja | H30: =IF(F30>=80,"🟢🟢 GANADOR FUERTE",IF(F30>=60,"🟢 GANADOR",IF(F30>=40,"🟡 POTENCIAL","🔴 DESCARTAR"))) | I30: 167 | J30: 16 | K30: — | L30: Chequia (CZK) | M30: 3 (Šicí cirkus, Dnes šiju, Duchajda) | N30: No | O30: No detectado | P30: Mujeres que cosen | Q30: Hobby / oficio | R30: Chequia (único mercado del Este con señal) | S30: Primer chequeo | T30: https://www.facebook.com/ads/library/?id=3425652864278046 | U30: Única señal real en Europa del Este; solo 1 anunciante sólido. | V30: 2026-10-04
A31: 2 | B31: OctoMaps (idiomas con mapas mentales: italiano, alemán) | C31: Tu pedido 04/10 | D31: Idiomas | E31: Pack de mapas mentales (+300) | F31: ='Score detalle'!H31 | G31: Media | H31: =IF(F31>=80,"🟢🟢 GANADOR FUERTE",IF(F31>=60,"🟢 GANADOR",IF(F31>=40,"🟡 POTENCIAL","🔴 DESCARTAR"))) | I31: 58.4 | J31: 25 | K31: — | L31: Moneda USD; copy en español (países no medidos) | M31: 2 (Maria, japonés +300 mapas mentales BRL; Tu Rincón de Idiomas MX, no idéntico) | N31: No | O31: No detectado | P31: Adultos 20-50 que quieren aprender un idioma rápido | Q31: Aprender una habilidad | R31: Argentina (italiano/alemán), México, España | S31: Primer chequeo | T31: https://www.facebook.com/ads/library/?id=1425862966088854 | U31: Cumple los 3 filtros: >20 días (58), >15 anuncios (25), pocos clones. Vi los 25 anuncios completos. Precio no visible. | V31: 2026-10-04
A32: Vigilar | B32: Geriactiva (biblioteca +1000 actividades para tercera edad) | C32: Tu pedido 04/10 | D32: Tercera edad / estimulación cognitiva | E32: Biblioteca de actividades PDF | F32: ='Score detalle'!H32 | G32: Media | H32: =IF(F32>=80,"🟢🟢 GANADOR FUERTE",IF(F32>=60,"🟢 GANADOR",IF(F32>=40,"🟡 POTENCIAL","🔴 DESCARTAR"))) | I32: 3.2 | J32: 181 | K32: — | L32: Moneda USD (países no medidos) | M32: 7+ con oferta casi idéntica (Mente activa AR, Academia Digital, Mente Activa, Mente Despierta BR, ActivaSenior ES, Vida Plena BR, Activa tu mente CL) | N32: Sí (ola de clones recién lanzados) | O32: Medio: '+3000 profesionales lo recomiendan' sin fuente | P32: Terapeutas ocupacionales, cuidadores y familiares de adultos mayores | Q32: Resolver un problema concreto / profesión | R32: Argentina (hay un competidor local en ARS), Chile, España | S32: Primer chequeo | T32: https://www.facebook.com/ads/library/?id=2363989227680463 | U32: 181 anuncios pero solo ≥3,2 días visibles: todo el rubro lanzó en los últimos días. Es ola reciente, no validación en el tiempo. | V32: 2026-10-04

Sheet Score detalle
A1: Producto | B1: Antigüedad (máx 20) | C1: Volumen (máx 20) | D1: Alcance (máx 15) | E1: Diversidad creativa (máx 10) | F1: Clonado (máx 20) | G1: Funnel (máx 15) | H1: Score total
A2: Aprende y Emprende (moldes de cuero y bolsos, voseo) | B2: 20 | C2: 20 | D2: 5 | E2: 7 | F2: 15 | G2: 0 | H2: =SUM(B2:G2)
A3: Udemia.IA (mini-cursos 'Dominá X en 7 días') | B3: 5 | C3: 20 | D3: 15 | E3: 10 | F3: 20 | G3: 0 | H3: =SUM(B3:G3)
A4: Navidad Creativa | B4: 20 | C4: 20 | D4: 5 | E4: 6 | F4: 15 | G4: 0 | H4: =SUM(B4:G4)
A5: Emprende con Arte (crochet 70% OFF) | B5: 20 | C5: 20 | D5: 5 | E5: 3 | F5: 15 | G5: 0 | H5: =SUM(B5:G5)
A6: Conocimiento Digital (megapack moldes de costura) | B6: 20 | C6: 20 | D6: 10 | E6: 2 | F6: 12 | G6: 0 | H6: =SUM(B6:G6)
A7: Carpintería para todos | B7: 10 | C7: 20 | D7: 5 | E7: 3 | F7: 20 | G7: 0 | H7: =SUM(B7:G7)
A8: La Biblioteca Definitiva De Tejido | B8: 20 | C8: 20 | D8: 5 | E8: 3 | F8: 15 | G8: 0 | H8: =SUM(B8:G8)
A9: Mundo Creativo (+2000 moldes goma eva) | B9: 20 | C9: 20 | D9: 5 | E9: 3 | F9: 15 | G9: 0 | H9: =SUM(B9:G9)
A10: 1500 Moldes de Costura | B10: 10 | C10: 20 | D10: 15 | E10: 4 | F10: 12 | G10: 0 | H10: =SUM(B10:G10)
A11: MonteAgro (manuales técnicos de cultivo) | B11: 5 | C11: 20 | D11: 15 | E11: 10 | F11: 5 | G11: 0 | H11: =SUM(B11:G11)
A12: Biblioteca Digital (planos y oficios) | B12: 5 | C12: 20 | D12: 5 | E12: 10 | F12: 15 | G12: 0 | H12: =SUM(B12:G12)
A13: Amigurumi Navideño | B13: 20 | C13: 10 | D13: 10 | E13: 2 | F13: 15 | G13: 0 | H13: =SUM(B13:G13)
... A32: Geriactiva (biblioteca +1000 actividades para tercera edad) | B32: 5 | C32: 20 | D32: 5 | E32: 7 | F32: 20 | G32: 0 | H32: =SUM(B32:G32)
A34: Notas: fórmula según references/scoring.md. Funnel = 0 en todos porque ninguna landing se pudo abrir (se normalizó: en tu planilla estaba en 3). Antigüedad = anuncio activo más viejo visto, cota inferior (la herramienta muestra los 50 más recientes). Clonado: 25+ anunciantes con la misma oferta = saturado (12). Alcance estimado por moneda/copy, no medido por país. La fórmula premia volumen y clones, por eso los nichos poco competidos puntúan menos por diseño; la prioridad de modelado combina score, competencia, mercado y encaje contigo.

Sheet Historial
A1: Producto | B1: Fecha | C1: Anuncios activos | D1: Antigüedad vista (días) | E1: Score | F1: Fuente
A2: Aprende y Emprende (moldes de cuero y bolsos, voseo) | B2: 2026-10-04 (1er chequeo) | C2: 7 | F2: Mi tracker
A3: Aprende y Emprende (moldes de cuero y bolsos, voseo) | B3: 2026-10-04 | C3: 33 | D3: 33 | E3: ='Lista maestra'!F2 | F3: Re-medición Ad Library
A4: Udemia.IA (mini-cursos 'Dominá X en 7 días') | B4: 2026-09-30 | C4: 336 | F4: Tu planilla
A5: Udemia.IA (mini-cursos 'Dominá X en 7 días') | B5: 2026-10-04 | C5: 411 | D5: 8 | E5: ='Lista maestra'!F3 | F5: Re-medición Ad Library
A6: Navidad Creativa | B6: 2026-10-04 (1er chequeo) | C6: 73 | F6: Mi tracker
A7: Navidad Creativa | B7: 2026-10-04 | C7: 73 | D7: 29 | E7: ='Lista maestra'!F4 | F7: Re-medición Ad Library
A8: Emprende con Arte (crochet 70% OFF) | B8: 2026-10-04 (1er chequeo) | C8: 6 | F8: Mi tracker
A9: Emprende con Arte (crochet 70% OFF) | B9: 2026-10-04 | C9: 62 | D9: 38.7 | E9: ='Lista maestra'!F5 | F9: Re-medición Ad Library
A10: Conocimiento Digital (megapack moldes de costura) | B10: 2026-09-30 | C10: 135 | F10: Tu planilla
A11: Conocimiento Digital (megapack moldes de costura) | B11: 2026-10-04 | C11: 140 | D11: 32 | E11: ='Lista maestra'!F6 | F11: Re-medición Ad Library
A12: Carpintería para todos | B12: 2026-10-04 (1er chequeo) | C12: 50 | F12: Mi tracker
A13: Carpintería para todos | B13: 2026-10-04 | C13: 145 | D13: 11.5 | E13: ='Lista maestra'!F7 | F13: Re-medición Ad Library
A14: La Biblioteca Definitiva De Tejido | B14: 2026-10-04 (1er chequeo) | C14: 54 | F14: Mi tracker
A15: La Biblioteca Definitiva De Tejido | B15: 2026-10-04 | C15: 54 | D15: 21.2 | E15: ='Lista maestra'!F8 | F15: Re-medición Ad Library
A16: Mundo Creativo (+2000 moldes goma eva) | B16: 2026-10-04 (1er chequeo) | C16: 29 | F16: Mi tracker
A17: Mundo Creativo (+2000 moldes goma eva) | B17: 2026-10-04 | C17: 29 | D17: 17.3 | E17: ='Lista maestra'!F9 | F17: Re-medición Ad Library
A18: 1500 Moldes de Costura | B18: 2026-10-04 (1er chequeo) | C18: 42 | F18: Mi tracker
A19: 1500 Moldes de Costura | B19: 2026-10-04 | C19: 68 | D19: 10 | E19: ='Lista maestra'!F10 | F19: Re-medición Ad Library
A20: MonteAgro (manuales técnicos de cultivo) | B20: 2026-09-30 | C20: 72 | F20: Tu planilla
A21: MonteAgro (manuales técnicos de cultivo) | B21: 2026-10-04 | C21: 108 | D21: 6.3 | E21: ='Lista maestra'!F11 | F21: Re-medición Ad Library
A22: Biblioteca Digital (planos y oficios) | B22: 2026-10-04 (1er chequeo) | C22: 26 | F22: Mi tracker
A23: Biblioteca Digital (planos y oficios) | B23: 2026-10-04 | C23: 26 | D23: 3.1 | E23: ='Lista maestra'!F12 | F23: Re-medición Ad Library
A24: Amigurumi Navideño | B24: 2026-09-30 | C24: 14 | F24: Tu planilla
A25: Amigurumi Navideño | B25: 2026-10-04 | C25: 15 | D25: 20.3 | E25: ='Lista maestra'!F13 | F25: Re-medición Ad Library
A26: Sofia Fernández (moldes de costura) | B26: 2026-09-30 | C26: 25 | F26: Tu planilla
A27: Sofia Fernández (moldes de costura) | B27: 2026-10-04 | C27: 47 | D27: 16 | E27: ='Lista maestra'!F14 | F27: Re-medición Ad Library
A28: Melissa Amicraft (amigurumi, pets por raza) | B28: 2026-09-30 | C28: 26 | F28: Tu planilla
A29: Melissa Amicraft (amigurumi, pets por raza) | B29: 2026-10-04 | C29: 36 | D29: 6.4 | E29: ='Lista maestra'!F15 | F29: Re-medición Ad Library
A30: Fermentados y kombucha (Escuela Vegetariana) | B30: 2026-10-04 (1er chequeo) | C30: 5 | F30: Mi tracker
A31: Fermentados y kombucha (Escuela Vegetariana) | B31: 2026-10-04 | C31: 31 | D31: 129.5 | E31: ='Lista maestra'!F16 | F31: Re-medición Ad Library
A32: MundoManuarte (velas artesanales) | B32: 2026-09-30 | C32: 9 | F32: Tu planilla
A33: MundoManuarte (velas artesanales) | B33: 2026-10-04 | C33: 8 | D33: 76.9 | E33: ='Lista maestra'!F17 | F33: Re-medición Ad Library
A34: Mentoría Global (empaques premium) | B34: 2026-10-04 (1er chequeo) | C34: 60 | F34: Mi tracker
A35: Mentoría Global (empaques premium) | B35: 2026-10-04 | C35: 60 | D35: 3.1 | E35: ='Lista maestra'!F18 | F35: Re-medición Ad Library
A36: Aprenda a Fazer Queijo (quesos) | B36: 2026-10-04 (1er chequeo) | C36: 8 | F36: Mi tracker
A37: Aprenda a Fazer Queijo (quesos) | B37: 2026-10-04 | C37: 8 | D37: 356 | E37: ='Lista maestra'!F19 | F37: Re-medición Ad Library
A38: Cursos de adiestramiento canino (EducaT Digital) | B38: 2026-10-04 (1er chequeo) | C38: 3 | F38: Mi tracker
A39: Cursos de adiestramiento canino (EducaT Digital) | B39: 2026-10-04 | C39: 3 | D39: 9.3 | E39: ='Lista maestra'!F20 | F39: Re-medición Ad Library
A40: Juana Castro (moldes de costura) | B40: 2026-09-30 | C40: 66 | F40: Tu planilla
...

Sheet Veredicto 05-10
A1: # | B1: Producto | C1: Score | D1: Veredicto | E1: Antigüedad (d) | F1: Anuncios | G1: Competidores | H1: Por qué | I1: Mercado | J1: Riesgo
A2: 1 | B2: Navidad / manualidades navideñas (modelo: Angelyc's Workshop) | C2: 73 | D2: 🟢 GANADOR | E2: 152.8 | F2: 56 | G2: 13-15 en el nicho | H2: 153 días corriendo + ventana estacional abierta ahora. En AR y ES el nicho está casi vacío: 7 y 6 anuncios, y la mayoría son de ellos. | I2: Argentina y España | J2: Ventana cierra el 24/12. Hay que lanzar en 2 semanas o se pierde el año.
A3: 2 | B3: La Biblioteca Definitiva De Tejido (+5200 patrones) | C3: 63 | D3: 🟢 GANADOR | E3: 36 | F3: 54 | G3: 2 | H3: Yo mismo vi esta página con el mismo creativo el 30/08: 36 días verificados, no 21. Solo 2 competidores. Octubre = empieza temporada de lana en el hemisferio norte. | I3: España y México | J3: Ticket bajo y producto fácil de piratear. Vive del volumen de creativos.
A4: 3 | B4: OctoMaps (idiomas con mapas mentales) | C4: 66 | D4: 🟢 GANADOR | E4: 58.4 | F4: 25 | G4: 2 | H4: La antigüedad más alta entre los de score alto (58 días) con solo 2 clones. Es el más validado en el tiempo de toda la planilla. | I4: Argentina, México, España | J4: Avatar nuevo para vos: no es manualidades. Tenés que construir el producto desde cero.
A6: — | B6: DESCARTADO de la prioridad #1 de la planilla:
A7: ✗ | B7: Aprende y Emprende (moldes de cuero y bolsos) | C7: 57 | D7: 🔴 NO ENTRAR AHORA | E7: 32.8 | F7: 17 | G7: 6+ | H7: Cayó de 33 a 17 anuncios en un día. Mientras tanto Pablo Gutierrez lanzó 28 anuncios en 2 días y MitiendaX clonó el hook textual ('No eras vos... era el molde') hace 1 día. Guerra de clones con el original apagándose. | I7: — | J7: Entrar hoy es pelear contra un entrante con más presupuesto en un nicho que el original está abandonando.
